Workbook

Sheet Portada
B8: Observatorio territorial de terrorismo y violencia armada en Colombia
B9: Base de datos depurada · Producto D
B11: Periodo | C11: Desde el 7 de agosto de 2026 (00:00, UTC−5)
B12: Fecha de corte | C12: 2026-10-25
B13: Registros en la base | C13: =COUNTA(Incidentes!A2:A35)
B14: Hojas | C14: Portada · Incidentes · Indicadores · Fuentes · Excluidos y pendientes · Metodología · Diccionario
B15: Elaboración | C15: GESEG – Gestión de la Seguridad S.A.S. · Del dato a la decisión.
B16: Nota | C16: Instrumento técnico con fuentes abiertas. No es producto de inteligencia ni de contrainteligencia. Los conteos por actor no equivalen a responsabilidad judicial. Revisión independiente pendiente de asignación.

Sheet Incidentes
A1: Id | B1: Fecha | C1: Hora | D1: Departamento | E1: Municipio | F1: Lugar | G1: Lat | H1: Lon | I1: Precisión coordenada | J1: Hecho | K1: Modalidad | L1: Objetivo | M1: Clase (analítica) | N1: Presunto autor | O1: Grupo | P1: Atribución | Q1: Muertos civiles | R1: Muertos FP | S1: Heridos civiles | T1: Heridos FP | U1: Total muertos | V1: Total heridos | W1: Nota de víctimas | X1: Evidencia | Y1: Daños | Z1: Económico | AA1: Desplazamiento | AB1: Servicios | AC1: Estado | AD1: Fuente 1 | AE1: Fuente 2 | AF1: Fuente 3 | AG1: N.º fuentes | AH1: Última verificación
A2: CO-2026-001 | B2: 46241 | C2: Tarde | D2: Huila | E2: Teruel | F2: Edificio de la Alcaldía y estación de Policía (casco urbano) | G2: 2.74 | H2: -75.57 | I2: Municipal aproximada | J2: Artefacto explosivo lanzado contra la sede de la Alcaldía, donde funciona la estación | K2: Granada / artefacto lanzado | L2: Infraestructura institucional y Fuerza Pública | M2: Presunto acto terrorista (clasificación analítica provisional) | N2: Disidencias de las FARC (atribución preliminar de las autoridades; la autoría sigue en investigación) | O2: Disidencias FARC | P2: B | Q2: 0 | R2: 0 | S2: 2 | T2: 0 | U2: =Q2+R2 | V2: =S2+T2 | W2: Dos contratistas de redes de internet heridos por esquirlas; gravedad no informada. | X2: Las autoridades señalaron preliminarmente a disidencias de las FARC; no hay decisión judicial. | Y2: Daños en el edificio de la Alcaldía (segundo piso). | Z2: No cuantificado | AA2: No documentado | AB2: No documentado | AC2: Preliminar | AD2: https://www.bluradio.com/nacion/atacan-con-explosivos-la-alcaldia-de-teruel-huila-hay-un-herido-so35 | AG2: =COUNTIF(AD2:AF2,"?*") | AH2: 2026-10-21
A3: CO-2026-002 | B3: 46242 | C3: Sin dato | D3: Cauca | E3: Santander de Quilichao | F3: Peaje de la vía Panamericana, sector Mondomo | G3: 3.01 | H3: -76.48 | I3: Municipal aproximada | J3: Vehículo con explosivos detonado en un peaje | K3: Vehículo con explosivos | L3: Infraestructura vial | M3: Presunto acto terrorista (clasificación analítica provisional) | N3: Disidencias de las FARC (atribución de las Fuerzas Militares, sin precisar la estructura) | O3: Disidencias FARC | P3: B | Q3: 0 | R3: 0 | S3: 2 | T3: 0 | U3: =Q3+R3 | V3: =S3+T3 | W3: Dos vigilantes con heridas leves. | X3: Las Fuerzas Militares atribuyeron el hecho a grupos disidentes de las FARC; no se nombró la estructura. | Y3: Peaje destruido o con daños graves según la cronología consultada. | Z3: No cuantificado | AA3: No documentado | AB3: Movilidad en la vía Panamericana (afectación no cuantificada) | AC3: Preliminar | AD3: https://www.aljazeera.com/news/2026/8/8/car-bomb-attack-rattles-colombia-after-inauguration-of-hardline-president | AE3: https://www.teleamazonas.com/actualidad/noticias/internacional/cronologia-violencia-colombia-atentados-seguridad-129149/ | AG3: =COUNTIF(AD3:AF3,"?*") | AH3: 2026-10-21
A4: CO-2026-003 | B4: 46242 | C4: Madrugada | D4: Cesar | E4: Curumaní | F4: Subestación de Policía San Roque (zona rural) | G4: 9.2 | H4: -73.54 | I4: Municipal aproximada | J4: Ataque con explosivos lanzados desde drones contra la subestación | K4: Dron con explosivos | L4: Fuerza Pública | M4: Ataque armado contra Fuerza Pública (clasificación analítica provisional) | N4: No identificado en las fuentes consultadas | O4: No determinado | P4: E | Q4: 0 | R4: 1 | S4: 0 | T4: 1 | U4: =Q4+R4 | V4: =S4+T4 | W4: Un subintendente muerto y un uniformado herido. | X4: Ninguna autoridad ha nombrado a los responsables. | Y4: Daños en la subestación no cuantificados. | Z4: No cuantificado | AA4: No documentado | AB4: No documentado | AC4: Preliminar | AD4: https://www.latribuna.hn/2026/08/08/policia-muere-en-ataque-con-explosivos-lanzados-desde-drones-en-colombia/ | AE4: https://www.minuto30.com/?p=1715502 | AF4: https://www.teleamazonas.com/actualidad/noticias/internacional/cronologia-violencia-colombia-atentados-seguridad-129149/ | AG4: =COUNTIF(AD4:AF4,"?*") | AH4: 2026-10-21
A5: CO-2026-004 | B5: 46249 | C5: Sin dato | D5: Norte de Santander | E5: Ábrego | F5: Eje vial (zona rural) | G5: 8.08 | H5: -73.22 | I5: Municipal aproximada | J5: Ataque con drones cargados de explosivos contra militares que hacían labores de seguridad | K5: Dron con explosivos | L5: Fuerza Pública | M5: Ataque armado contra Fuerza Pública (clasificación analítica provisional) | N5: ELN (presuntamente, según el Ministerio de Defensa y el Ejército) | O5: ELN | P5: B | Q5: 0 | R5: 1 | S5: 0 | T5: 5 | U5: =Q5+R5 | V5: =S5+T5 | W5: Un soldado profesional muerto y cinco heridos. | X5: El Ministerio de Defensa atribuyó el hecho al ELN en sus redes y el Ejército lo describe como presuntamente perpetrado por el ELN. | Y5: No informados. | Z5: No cuantificado | AA5: No documentado | AB5: No documentado | AC5: Confirmado | AD5: https://www.infobae.com/america/agencias/2026/08/16/al-menos-un-militar-muerto-y-otros-cinco-heridos-en-un-ataque-del-eln-en-el-noreste-de-colombia/ | AE5: https://www.teleamazonas.com/actualidad/noticias/internacional/10-hechos-violentos-colombia-atentados-espriella-129149/ | AG5: =COUNTIF(AD5:AF5,"?*") | AH5: 2026-10-21
A6: CO-2026-005 | B6: 46261 | C6: Sin dato | D6: Cesar | E6: Pelaya | F6: Zona rural; pelotón del Batallón Especial Energético y Vial N.º 3 | G6: 8.69 | H6: -73.67 | I6: Municipal aproximada | J6: Ataque con drones y más de 40 artefactos explosivos contra tropas | K6: Dron con explosivos | L6: Fuerza Pública | M6: Ataque armado contra Fuerza Pública (clasificación analítica provisional) | N6: ELN (atribución preliminar de autoridades sin precisar; el Ejército lo vincula a una posible retaliación) | O6: ELN | P6: D | Q6: 0 | R6: 0 | S6: 0 | T6: 2 | U6: =Q6+R6 | V6: =S6+T6 | W6: Dos soldados heridos (uno grave). | X6: Autoridades no identificadas atribuyeron preliminarmente el hecho a estructuras del ELN; el Ejército no nombra al autor. | Y6: No informados. | Z6: No cuantificado | AA6: No documentado | AB6: No documentado | AC6: Preliminar | AD6: https://www.noticiasrcn.com/colombia/lanzan-granadas-contra-batallon-en-pelaya-cesar-1054870 | AE6: https://lapatilla.com/2026/08/27/al-menos-dos-soldados-fueron-heridos-por-ataque-con-explosivos-en-el-norte-de-colombia/ | AF6: https://www.teleamazonas.com/actualidad/noticias/internacional/cronologia-violencia-colombia-atentados-seguridad-129149/ | AG6: =COUNTIF(AD6:AF6,"?*") | AH6: 2026-10-21
A7: CO-2026-006 | B7: 46263 | C7: Noche | D7: Cesar | E7: Pailitas | F7: Estación de Policía (casco urbano) | G7: 8.96 | H7: -73.63 | I7: Municipal aproximada | J7: Ataque con drones cargados de explosivos y ráfagas de fusil contra la estación | K7: Dron con explosivos | L7: Fuerza Pública | M7: Ataque armado contra Fuerza Pública (clasificación analítica provisional) | N7: ELN (según un medio que cita a autoridades locales; no confirmado) | O7: ELN | P7: D | Q7: 0 | R7: 0 | S7: 0 | T7: 3 | U7: =Q7+R7 | V7: =S7+T7 | W7: Tres policías heridos. | X7: Solo un medio atribuye el hecho al ELN, citando autoridades locales sin identificar. | Y7: Daños en el área de alojamiento de la estación. | Z7: No cuantificado | AA7: No documentado | AB7: No documentado | AC7: Preliminar | AD7: https://www.noticiasrcn.com/colombia/ataque-con-drones-contra-estacion-en-pailitas-dejo-tres-policias-heridos-se-le-atribuye-al-eln-1055649 | AE7: https://www.eluniversal.com.co/sucesos/2026/08/30/video-atacan-con-drones-estacion-de-policia-en-pailitas-cesar-3-uniformados-heridos/ | AG7: =COUNTIF(AD7:AF7,"?*") | AH7: 2026-10-21
A8: CO-2026-007 | B8: 46265 | C8: 23:15 | D8: Norte de Santander | E8: Los Patios | F8: Frente a la estación de Policía | G8: 7.84 | H8: -72.51 | I8: Municipal aproximada | J8: Carro bomba (cerca de 80 kg de amonal activados por radiofrecuencia según la Policía) | K8: Vehículo con explosivos | L8: Fuerza Pública y población civil | M8: Presunto acto terrorista (clasificación analítica provisional) | N8: Frente de Guerra Urbano Carlos Germán Velasco del ELN (atribución de la Policía; en investigación) | O8: ELN | P8: B | Q8: 1 | R8: 0 | S8: 9 | T8: 2 | U8: =Q8+R8 | V8: =S8+T8 | W8: Un civil muerto; 11 heridos, entre ellos dos policías. | X8: La Policía Nacional atribuyó el ataque a esa estructura del ELN; no hay decisión judicial. | Y8: Daños en la infraestructura policial; vehículos y motocicletas incinerados. | Z8: No cuantificado | AA8: No documentado | AB8: No documentado | AC8: Confirmado | AD8: https://www.infobae.com/colombia/2026/09/02/atentados-con-explosivos-en-colombia-llegan-a-204-en-2026-tras-carro-bomba-en-los-patios/ | AE8: https://www.emol.com/noticias/Internacional/2026/09/01/1210192/colombia-atentado-auto-bomba.html | AF8: https://www.teleamazonas.com/actualidad/noticias/internacional/cronologia-violencia-colombia-atentados-seguridad-129149/ | AG8: =COUNTIF(AD8:AF8,"?*") | AH8: 2026-10-21
A9: CO-2026-008 | B9: 46267 | C9: Madrugada | D9: Cesar | E9: Pailitas | F9: Subestación de Policía de El Burro | G9: 8.96 | H9: -73.63 | I9: Municipal aproximada | J9: Ataque con drones que lanzaron varios explosivos; el personal había sido trasladado previamente | K9: Dron con explosivos | L9: Fuerza Pública | M9: Ataque armado contra Fuerza Pública (clasificación analítica provisional) | N9: No identificado en la fuente consultada | O9: No determinado | P9: E | Q9: 0 | R9: 0 | S9: 0 | T9: 0 | U9: =Q9+R9 | V9: =S9+T9 | W9: Sin heridos. | X9: Ninguna autoridad ha nombrado a los responsables. | Y9: Daños en la estructura de la subestación. | Z9: No cuantificado | AA9: No documentado | AB9: No documentado | AC9: Preliminar | AD9: https://www.vanguardia.com/colombia/2026/09/02/nuevo-ataque-con-drones-golpeo-estacion-de-policia-en-el-burro-cesar/ | AG9: =COUNTIF(AD9:AF9,"?*") | AH9: 2026-10-21
A10: CO-2026-009 | B10: 46269 | C10: 19:20 | D10: Norte de Santander | E10: Ocaña | F10: Cantón Militar El Trapiche | G10: 8.25 | H10: -73.36 | I10: Municipal aproximada | J10: Ataque con enjambre de drones con explosivos contra el cantón militar | K10: Dron con explosivos | L10: Fuerza Pública | M10: Ataque armado contra Fuerza Pública (clasificación analítica provisional) | N10: Frente Camilo Torres Restrepo del ELN (atribución del Ejército) | O10: ELN | P10: B | Q10: 0 | R10: 3 | S10: 0 | T10: 4 | U10: =Q10+R10 | V10: =S10+T10 | W10: Tres militares muertos (uno falleció al día siguiente) y cuatro heridos. | X10: El Ejército atribuyó el hecho al ELN; el presidente anunció una ofensiva en el Catatumbo. | Y10: Una aeronave de la Fuerza Aérea alcanzada por esquirlas, según el Presidente. | Z10: No cuantificado | AA10: No documentado | AB10: No documentado | AC10: Confirmado | AD10: https://www.eluniversal.com.co/colombia/2026/09/05/eln-ataco-base-militar-en-ocana-con-drones-cargados-de-explosivos/ | AE10: https://www.minuto30.com/amp/muere-jhon-carlos-soldado-ataque-ocana/1718094/ | AF10: https://www.noticiasrcn.com/colombia/ataque-con-drones-del-eln-en-ocana-deja-dos-militares-muertos-y-cinco-heridos-1057923 | AG10: =COUNTIF(AD10:AF10,"?*") | AH10: 2026-10-21
A11: CO-2026-010 | B11: 46287 | C11: Noche | D11: La Guajira | E11: Uribia | F11: Línea férrea de Cerrejón, kilómetro 60 | G11: 11.71 | H11: -72.27 | I11: Municipal aproximada | J11: Detonación de explosivos que descarriló un tren vacío | K11: Explosivo / IED | L11: Infraestructura minera y férrea | M11: Incierto – autoría y finalidad no establecidas | N11: No establecido | O11: No determinado | P11: E | Q11: 0 | R11: 0 | S11: 0 | T11: 0 | U11: =Q11+R11 | V11: =S11+T11 | W11: Sin víctimas; el convoy iba vacío. | X11: Ninguna autoridad ha confirmado a los responsables. | Y11: Vagones descarrilados; la empresa evalúa los daños. Sexto ataque de 2026 contra infraestructura de Cerrejón, según la empresa. | Z11: No cuantificado | AA11: No documentado | AB11: Transporte ferroviario de carbón | AC11: Preliminar | AD11: https://es.euronews.com/2026/09/23/un-ataque-con-explosivos-descarrila-un-tren-de-cerrejon-en-el-norte-de-colombia | AE11: https://www.teleamazonas.com/actualidad/noticias/internacional/atentado-explosivos-tren-cerrejon-militarizacion-santa-marta-128719/ | AG11: =COUNTIF(AD11:AF11,"?*") | AH11: 2026-10-21
A12: CO-2026-011 | B12: 46287 | C12: Sin dato | D12: Magdalena | E12: Santa Marta | F12: Troncal del Caribe y zonas urbanas | G12: 11.24 | H12: -74.2 | I12: Municipal aproximada | J12: Quema de vehículos, bloqueos e intimidaciones tras un operativo contra las ACSN; un comunicado en redes planteó un paro | K12: Paro armado | L12: Población civil y transporte | M12: Incierto – autoría y finalidad no establecidas | N12: Autodefensas Conquistadoras de la Sierra Nevada (según medios) | O12: ACSN | P12: D | Q12: 0 | R12: 0 | S12: 0 | T12: 0 | U12: =Q12+R12 | V12: =S12+T12 | W12: No se reportan víctimas de estos hechos. | X12: Medios vinculan los hechos con las ACSN; aún no hay confirmación oficial. | Y12: Vehículos incendiados y comercio afectado; sin cuantificar. | Z12: No cuantificado | AA12: No documentado | AB12: Transporte y comercio; Troncal del Caribe | AC12: En investigación | AD12: https://cambiocolombia.com/pais/articulo/2026/9/paro-armado-santa-marta-primeras-horas-ataques-vehiculos-quemados-respuesta-autoridades | AE12: https://cambiocolombia.com/pais/articulo/2026/9/hay-paro-armado-en-santa-marta-las-autoridades-lo-niegan-pero-se-reportan-situaciones-de-orden-publico/ | AF12: https://www.teleamazonas.com/actualidad/noticias/internacional/cronologia-violencia-colombia-atentados-seguridad-129149/ | AG12: =COUNTIF(AD12:AF12,"?*") | AH12: 2026-10-21
A13: CO-2026-012 | B13: 46289 | C13: Sin dato | D13: Cesar | E13: Aguachica | F13: Estación de Policía | G13: 8.31 | H13: -73.61 | I13: Municipal aproximada | J13: Ataque con dos drones que lanzaron cuatro granadas | K13: Dron con explosivos | L13: Fuerza Pública | M13: Ataque armado contra Fuerza Pública (clasificación analítica provisional) | N13: No identificado | O13: No determinado | P13: E | Q13: 0 | R13: 0 | S13: 0 | T13: 0 | U13: =Q13+R13 | V13: =S13+T13 | W13: Sin heridos. | X13: Ninguna autoridad ha nombrado a los responsables. | Y13: Daños en infraestructura de la estación. | Z13: No cuantificado | AA13: No documentado | AB13: No documentado | AC13: Preliminar | AD13: https://minuto60.com/judicial/estacion-policia-fue-atacada-drones-explosivos-cesar/16594 | AE13: https://www.teleamazonas.com/actualidad/noticias/internacional/cronologia-violencia-colombia-atentados-seguridad-129149/ | AG13: =COUNTIF(AD13:AF13,"?*") | AH13: 2026-10-21
A14: CO-2026-013 | B14: 46294 | C14: Sin dato | D14: Chocó | E14: Condoto | F14: Estación de Policía | G14: 5.09 | H14: -76.65 | I14: Municipal aproximada | J14: Cuatro cargas explosivas lanzadas contra la estación (primer día de una ola de ataques) | K14: Dron con explosivos | L14: Fuerza Pública | M14: Ataque armado contra Fuerza Pública (clasificación analítica provisional) | N14: ELN (atribución de la Defensoría del Pueblo) | O14: ELN | P14: B | Q14: 0 | R14: 0 | S14: 0 | T14: 1 | U14: =Q14+R14 | V14: =S14+T14 | W14: Un intendente herido. | X14: La Defensoría del Pueblo atribuyó la ola de ataques al ELN. | Y14: No informados. | Z14: No cuantificado | AA14: No documentado | AB14: No documentado | AC14: Preliminar | AD14: https://www.vanguardia.com/colombia/2026/10/02/tres-dias-de-ataques-con-drones-en-choco-esto-se-sabe-de-la-ofensiva-contra-la-fuerza-publica/ | AE14: https://www.asuntoslegales.com.co/actualidad/gobernadora-del-choco-alerta-por-11-ataques-con-drones-en-los-ultimos-tres-dias-4494689 | AG14: =COUNTIF(AD14:AF14,"?*") | AH14: 2026-10-21
A15: CO-2026-014 | B15: 46295 | C15: Sin dato | D15: Chocó | E15: Nóvita | F15: Unidades de Policía y Ejército | G15: 4.95 | H15: -76.64 | I15: Municipal aproximada | J15: Seis ataques con drones contra unidades de la Policía y el Ejército | K15: Dron con explosivos | L15: Fuerza Pública | M15: Ataque armado contra Fuerza Pública (clasificación analítica provisional) | N15: ELN (atribución de la Defensoría del Pueblo) | O15: ELN | P15: B | Q15: 0 | R15: 0 | S15: 0 | T15: 0 | U15: =Q15+R15 | V15: =S15+T15 | W15: No se reportan víctimas. | X15: La Defensoría del Pueblo atribuyó la ola de ataques al ELN. | Y15: No informados. | Z15: No cuantificado | AA15: No documentado | AB15: No documentado | AC15: Preliminar | AD15: https://www.vanguardia.com/colombia/2026/10/02/tres-dias-de-ataques-con-drones-en-choco-esto-se-sabe-de-la-ofensiva-contra-la-fuerza-publica/ | AE15: https://www.semana.com/nacion/articulo/gobernadora-del-choco-alerta-por-ola-de-ataques-con-drones-11-en-tres-dias/202631/ | AG15: =COUNTIF(AD15:AF15,"?*") | AH15: 2026-10-21
A16: CO-2026-015 | B16: 46296 | C16: Sin dato | D16: Chocó | E16: Río Iró | F16: Estación de Policía de Santa Rita de Iró | G16: 5.17 | H16: -76.55 | I16: Municipal aproximada | J16: Ataque masivo con drones y explosivos contra la estación | K16: Dron con explosivos | L16: Fuerza Pública | M16: Ataque armado contra Fuerza Pública (clasificación analítica provisional) | N16: ELN (atribución de la Defensoría del Pueblo) | O16: ELN | P16: B | Q16: 0 | R16: 0 | S16: 0 | T16: 0 | U16: =Q16+R16 | V16: =S16+T16 | W16: No se reportan víctimas. | X16: La Defensoría del Pueblo atribuyó la ola de ataques al ELN. | Y16: No informados. | Z16: No cuantificado | AA16: No documentado | AB16: No documentado | AC16: Preliminar | AD16: https://www.vanguardia.com/colombia/2026/10/01/atencion-atacan-con-drones-y-explosivos-estacion-de-policia-de-santa-rita-de-iro-choco/ | AE16: https://www.vanguardia.com/colombia/2026/10/02/tres-dias-de-ataques-con-drones-en-choco-esto-se-sabe-de-la-ofensiva-contra-la-fuerza-publica/ | AG16: =COUNTIF(AD16:AF16,"?*") | AH16: 2026-10-21
A17: CO-2026-016 | B17: 46298 | C17: Sin dato | D17: Huila | E17: Neiva | F17: Vereda Aipecito (zona rural); fecha de la primera nota publicada | G17: 2.93 | H17: -75.28 | I17: Municipal aproximada | J17: Ataque con explosivos lanzados desde drones contra soldados del Batallón de Artillería N.º 9 Tenerife | K17: Dron con explosivos | L17: Fuerza Pública | M17: Ataque armado contra Fuerza Pública (clasificación analítica provisional) | N17: Frente Ismael Ruiz de las disidencias de Iván Mordisco (atribución del Ejército) | O17: Disidencias FARC | P17: B | Q17: 0 | R17: 1 | S17: 0 | T17: 1 | U17: =Q17+R17 | V17: =S17+T17 | W17: Un soldado profesional muerto y otro herido por esquirlas. | X17: El Ejército atribuyó el hecho a esa estructura disidente. | Y17: No informados. | Z17: No cuantificado | AA17: No documentado | AB17: No documentado | AC17: Confirmado | AD17: https://www.vanguardia.com/colombia/2026/10/03/asi-fue-el-ataque-con-drones-que-dejo-un-soldado-muerto-y-otro-herido-en-huila/ | AE17: https://cambiocolombia.com/conflicto-armado-en-colombia/articulo/2026/10/disidencias-de-mordisco-atacan-con-drones-a-militares-en-zona-rural-de-neiva-un-soldado-muerto-y-otro-herido | AG17: =COUNTIF(AD17:AF17,"?*") | AH17: 2026-10-21
A18: CO-2026-017 | B18: 46300 | C18: 01:10 | D18: Cesar | E18: Aguachica | F18: Estación de Policía | G18: 8.31 | H18: -73.61 | I18: Municipal aproximada | J18: Ataque con drones y explosivos, con ráfagas de fusil; se fugaron tres detenidos | K18: Dron con explosivos | L18: Fuerza Pública | M18: Ataque armado contra Fuerza Pública (clasificación analítica provisional) | N18: ELN como primera línea de investigación (no verificada) | O18: ELN | P18: D | Q18: 0 | R18: 0 | S18: 1 | T18: 0 | U18: =Q18+R18 | V18: =S18+T18 | W18: Un detenido con una lesión en una pierna. | X18: Autoridades locales apuntan al ELN como hipótesis; no hay atribución definitiva. | Y18: Daños concentrados en un muro de la estación. | Z18: No cuantificado | AA18: No documentado | AB18: No documentado | AC18: En investigación | AD18: https://www.vanguardia.com/colombia/2026/10/05/nueva-noche-de-tension-en-aguachica-tras-ataque-con-explosivos-a-estacion-de-policia/ | AE18: https://www.elpais.com.co/judicial/asointermedias-rechaza-nuevo-ataque-con-drones-contra-la-estacion-de-policia-de-aguachica-cesar-0506.html | AG18: =COUNTIF(AD18:AF18,"?*") | AH18: 2026-10-21
A19: CO-2026-018 | B19: 46302 | C19: 11:34 | D19: Cauca | E19: Popayán | F19: Entre los barrios Santa Mónica y Alfonso López | G19: 2.44 | H19: -76.61 | I19: Municipal aproximada | J19: Detonación de un artefacto explosivo cerca de un puesto de control policial | K19: Explosivo / IED | L19: Fuerza Pública y población civil | M19: Incierto – autoría y finalidad no establecidas | N19: No atribuido | O19: No determinado | P19: E | Q19: 0 | R19: 0 | S19: 0 | T19: 2 | U19: =Q19+R19 | V19: =S19+T19 | W19: Dos policías gravemente heridos; civiles afectados sin cifra consolidada. | X19: No hay atribución oficial. | Y19: No descritos. | Z19: No cuantificado | AA19: No documentado | AB19: No documentado | AC19: Preliminar | AD19: https://www.publimetro.co/noticias/2026/10/07/terror-en-popayan-atentado-con-explosivos-deja-al-menos-a-dos-policias-gravemente-heridos/ | AG19: =COUNTIF(AD19:AF19,"?*") | AH19: 2026-10-21
A20: CO-2026-019 | B20: 46306 | C20: Sin dato | D20: Valle del Cauca | E20: Tuluá | F20: Corregimiento La Marina (zona rural); fecha de la primera nota publicada | G20: 4.08 | H20: -76.2 | I20: Municipal aproximada | J20: Disparos contra policías que acudieron a un llamado de emergencia que sería una trampa | K20: Ataque armado | L20: Fuerza Pública | M20: Ataque armado contra Fuerza Pública (clasificación analítica provisional) | N20: Frente 57 de las disidencias de las FARC (primeras informaciones; la Policía vincula al atacante abatido) | O20: Disidencias FARC | P20: B | Q20: 0 | R20: 1 | S20: 0 | T20: 1 | U20: =Q20+R20 | V20: =S20+T20 | W20: Un policía muerto y otro herido; un presunto atacante abatido (no contado entre las víctimas). | X20: La Policía indicó que el atacante neutralizado haría parte de ese frente; la atribución es de primeras informaciones. | Y20: No informados. | Z20: No cuantificado | AA20: No documentado | AB20: No documentado | AC20: Preliminar | AD20: https://www.semana.com/nacion/cali/articulo/video-muestra-el-momento-en-el-que-disidentes-atacan-a-disparos-a-policias-en-valle-del-cauca-un-uniformado-fue-asesinado/202640/ | AG20: =COUNTIF(AD20:AF20,"?*") | AH20: 2026-10-21
A21: CO-2026-020 | B21: 46308 | C21: Sin dato | D21: Valle del Cauca | E21: Jamundí | F21: Subestación de Policía de Potrerito (zona rural) | G21: 3.26 | H21: -76.54 | I21: Municipal aproximada | J21: Ataque con drones contra la subestación | K21: Dron con explosivos | L21: Fuerza Pública | M21: Ataque armado contra Fuerza Pública (clasificación analítica provisional) | N21: Frente Jaime Martínez de las disidencias (atribución preliminar) | O21: Disidencias FARC | P21: D | Q21: 0 | R21: 0 | S21: 0 | T21: 0 | U21: =Q21+R21 | V21: =S21+T21 | W21: No se reportan víctimas en la fuente consultada. | X21: Fuente secundaria que cita una atribución preliminar sin identificar a la autoridad. | Y21: No informados. | Z21: No cuantificado | AA21: No documentado | AB21: No documentado | AC21: Preliminar | AD21: https://90minutos.co/judicial/reportan-ataque-drones-zona-rural-jamundi-valle-cauca-13-10-2026/ | AG21: =COUNTIF(AD21:AF21,"?*") | AH21: 2026-10-21
A22: CO-2026-021 | B22: 46309 | C22: Noche | D22: Chocó | E22: San José del Palmar | F22: Vereda Alto del Oso (instalaciones militares) | G22: 4.9 | H22: -76.23 | I22: Municipal aproximada | J22: Ataque con drones y granadas contra tropas; 21 granadas detonadas según la Gobernadora | K22: Dron con explosivos | L22: Fuerza Pública | M22: Ataque armado contra Fuerza Pública (clasificación analítica provisional) | N22: Frente Ernesto Che Guevara del ELN (atribución preliminar del Ejército) | O22: ELN | P22: B | Q22: 0 | R22: 0 | S22: 0 | T22: 9 | U22: =Q22+R22 | V22: =S22+T22 | W22: Nueve militares heridos, evacuados a Medellín. | X22: El Ejército atribuyó el ataque a esa estructura del ELN, en términos preliminares. | Y22: No informados. | Z22: No cuantificado | AA22: No documentado | AB22: No documentado | AC22: Preliminar | AD22: https://www.infobae.com/colombia/2026/10/15/ataque-con-drones-atribuido-al-eln-en-san-jose-del-palmar-choco-dejo-un-saldo-de-nueve-militares-heridos/ | AE22: https://www.noticiasrcn.com/colombia/nueve-soldados-resultaron-heridos-por-ataque-con-drones-en-san-jose-del-palmar-choco-1071590 | AF22: https://www.defensoria.gov.co/web/guest/w/llamamos-a-proteger-a-la-poblacion-civil-tras-ataque-con-drones-que-dejo-nueve-militares-heridos-en-san-jose-del-palmar-choco | AG22: =COUNTIF(AD22:AF22,"?*") | AH22: 2026-10-21
A23: CO-2026-022 | B23: 46310 | C23: Mañana | D23: Valle del Cauca | E23: Cali | F23: Oriente de la ciudad; patrulla de la Policía en control preventivo | G23: 3.45 | H23: -76.53 | I23: Municipal aproximada | J23: Granada lanzada contra una patrulla; un hombre fue capturado tras una persecución | K23: Granada / artefacto lanzado | L23: Fuerza Pública | M23: Ataque armado contra Fuerza Pública (clasificación analítica provisional) | N23: Disidencias de las FARC (según la Alcaldía, por los presuntos nexos del capturado) | O23: Disidencias FARC | P23: D | Q23: 0 | R23: 0 | S23: 0 | T23: 5 | U23: =Q23+R23 | V23: =S23+T23 | W23: Cinco policías heridos. | X23: El Alcalde informó que el capturado tendría nexos con disidencias; no hay decisión judicial. | Y23: No informados. | Z23: No cuantificado | AA23: No documentado | AB23: No documentado | AC23: En investigación | AD23: https://www.infobae.com/colombia/2026/10/16/alejandro-eder-entrego-nuevos-detalles-del-atentado-que-dejo-cinco-policias-heridos-en-el-oriente-de-cali-capturado-tendria-nexos-con-las-disidencias-de-las-farc/ | AE23: https://www.qhubocali.com/judiciales/explosion-sacudio-a-cali-cuatro-policias-y-una-civil-resultaron-heridos/ | AG23: =COUNTIF(AD23:AF23,"?*") | AH23: 2026-10-21
A24: CO-2026-023 | B24: 46310 | C24: Mañana | D24: Huila | E24: Palermo | F24: Estación de Policía en la plaza principal | G24: 2.89 | H24: -75.43 | I24: Municipal aproximada | J24: Ataque con drones cargados con explosivos contra la estación | K24: Dron con explosivos | L24: Fuerza Pública | M24: Ataque armado contra Fuerza Pública (clasificación analítica provisional) | N24: No identificado | O24: No determinado | P24: E | Q24: 0 | R24: 0 | S24: 0 | T24: 2 | U24: =Q24+R24 | V24: =S24+T24 | W24: Dos policías heridos. | X24: Las fuentes no atribuyen el hecho. | Y24: Daños en una vivienda cercana. | Z24: No cuantificado | AA24: No documentado | AB24: Alcaldía evacuada | AC24: Preliminar | AD24: https://www.eluniversal.com.co/sucesos/2026/10/15/video-violento-ataque-con-drones-a-estacion-de-policia-en-palermo-huila/ | AE24: https://www.bluradio.com/nacion/ataque-con-explosivos-lanzados-desde-drones-deja-dos-policias-heridos-en-palermo-huila-pr30 | AF24: https://www.defensoria.gov.co/web/guest/w/comunidades-del-occidente-del-departamento-del-huila-estan-en-riesgo-tras-reciente-escalada-de-violencia | AG24: =COUNTIF(AD24:AF24,"?*") | AH24: 2026-10-21
A25: CO-2026-024 | B25: 46311 | C25: Sin dato | D25: Huila | E25: Teruel | F25: Estación de Policía en el edificio de la Alcaldía | G25: 2.74 | H25: -75.57 | I25: Municipal aproximada | J25: Ataque con drones: al menos cuatro cargas explosivas | K25: Dron con explosivos | L25: Fuerza Pública e infraestructura institucional | M25: Ataque armado contra Fuerza Pública (clasificación analítica provisional) | N25: No atribuido (en la zona opera el Frente Ismael Ruiz; esto es solo contexto) | O25: No determinado | P25: E | Q25: 0 | R25: 0 | S25: 0 | T25: 1 | U25: =Q25+R25 | V25: =S25+T25 | W25: Un policía herido. | X25: Ninguna autoridad ha nombrado a los responsables en las fuentes consultadas. | Y25: Graves daños en paredes, techos y ventanas del palacio municipal. | Z25: No cuantificado | AA25: No documentado | AB25: Personal municipal evacuado | AC25: Preliminar | AD25: https://www.vanguardia.com/colombia/2026/10/16/ataque-con-drones-en-teruel-huila-dejo-un-policia-herido-y-afecto-instalaciones-oficiales/ | AE25: https://www.lafm.com.co/orden-publico/ataque-drones-teruel-huila-414206 | AG25: =COUNTIF(AD25:AF25,"?*") | AH25: 2026-10-21
A26: CO-2026-025 | B26: 46312 | C26: 08:10 | D26: Valle del Cauca | E26: Cali | F26: Montebello, vía a Tres Cruces | G26: 3.45 | H26: -76.53 | I26: Municipal aproximada | J26: Dos artefactos explosivos: uno al paso de una patrulla y otro minutos después, cuando llegaba el grupo antiexplosivos | K26: Explosivo / IED | L26: Fuerza Pública | M26: Presunto acto terrorista (clasificación analítica provisional) | N26: Estructura Jaime Martínez de las disidencias (atribución del Alcalde de Cali) | O26: Disidencias FARC | P26: B | Q26: 0 | R26: 0 | S26: 0 | T26: 3 | U26: =Q26+R26 | V26: =S26+T26 | W26: Tres policías heridos. | X26: El Alcalde de Cali atribuyó los hechos a esa estructura; no hay decisión judicial. | Y26: No informados. | Z26: No cuantificado | AA26: No documentado | AB26: No documentado | AC26: Preliminar | AD26: https://www.infobae.com/colombia/2026/10/17/ataque-con-explosivos-dejo-tres-uniformados-lesionados-en-cali/ | AE26: https://www.elheraldo.co/colombia/2026/10/17/detonacion-de-artefactos-explosivos-en-zona-rural-de-cali-deja-tres-policias-heridos/ | AF26: https://www.eluniversal.com.co/colombia/2026/10/17/explosivos-contra-la-policia-en-cali-cuatro-uniformados-heridos/ | AG26: =COUNTIF(AD26:AF26,"?*") | AH26: 2026-10-21
A27: CO-2026-026 | B27: 46316 | C27: 01:30 | D27: Cesar | E27: Pelaya | F27: Estación de Policía | G27: 8.69 | H27: -73.67 | I27: Municipal aproximada | J27: Cuatro ráfagas de descargas lanzadas desde drones contra la estación (segundo ataque similar al municipio) | K27: Dron con explosivos | L27: Fuerza Pública | M27: Ataque armado contra Fuerza Pública (clasificación analítica provisional) | N27: No identificado por las autoridades | O27: No determinado | P27: E | Q27: 0 | R27: 0 | S27: 0 | T27: 6 | U27: =Q27+R27 | V27: =S27+T27 | W27: Seis policías heridos, dos con complicaciones. | X27: La Gobernación se refiere a 'violentos' y no nombra a ningún grupo. | Y27: Cuatro granadas impactaron la estación. | Z27: No cuantificado | AA27: No documentado | AB27: No documentado | AC27: Preliminar | AD27: https://www.elheraldo.co/colombia/2026/10/21/ataque-con-drones-contra-estacion-de-policia-en-pelaya-cesar-deja-seis-uniformados-heridos/ | AE27: https://www.infobae.com/colombia/2026/10/21/nuevo-ataque-con-drones-contra-una-estacion-de-policia-en-colombia-dejo-seis-uniformados-heridos-autoridades-ofrecieron-millonaria-recompensa/ | AG27: =COUNTIF(AD27:AF27,"?*") | AH27: 2026-10-21
A28: CO-2026-027 | B28: 46241 | C28: Tarde | D28: Arauca | E28: Fortul | F28: Cerca de la Concentración Educativa Elvira Walteros | G28: 6.8 | H28: -71.77 | I28: Municipal aproximada | J28: Artefacto explosivo lanzado contra la Fuerza Pública que cayó junto a una vivienda | K28: Granada / artefacto lanzado | L28: Fuerza Pública (afectó a una vivienda) | M28: Ataque armado contra Fuerza Pública (clasificación analítica provisional) | N28: ELN (atribución del Ejército) | O28: ELN | P28: B | Q28: 0 | R28: 0 | S28: 0 | T28: 0 | U28: =Q28+R28 | V28: =S28+T28 | W28: Sin muertos ni heridos; una familia en riesgo. | X28: El Ejército atribuyó el hecho al ELN y lo denunció ante organismos nacionales e internacionales. | Y28: Daños graves en la estructura de una vivienda. | Z28: No cuantificado | AA28: No documentado | AB28: No documentado | AC28: Preliminar | AD28: https://www.semana.com/nacion/articulo/familia-por-poco-muere-tras-ataque-con-explosivos-del-eln-en-arauca-ejercito-denuncio-a-la-guerrilla-ante-organismos-internacionales/202617/ | AG28: =COUNTIF(AD28:AF28,"?*") | AH28: 2026-10-21
A29: CO-2026-028 | B29: 46299 | C29: 07:50 | D29: Nariño | E29: El Peñol | F29: Estación de Policía (casco urbano) | G29: 1.45 | H29: -77.43 | I29: Municipal aproximada | J29: Hostigamiento con ráfagas de fusil y artefactos explosivos, posiblemente lanzados desde drones; decenas de familias salieron del casco urbano | K29: Dron con explosivos | L29: Fuerza Pública | M29: Ataque armado contra Fuerza Pública (clasificación analítica provisional) | N29: No atribuido: las fuentes mencionan la confluencia del ELN y disidencias, sin atribución | O29: No determinado | P29: E | Q29: 0 | R29: 0 | S29: 0 | T29: 0 | U29: =Q29+R29 | V29: =S29+T29 | W29: Heridos aún sin confirmar. | X29: Ninguna autoridad ha nombrado a los responsables. | Y29: Se verifican daños en viviendas e infraestructura cercana. | Z29: No cuantificado | AA29: Evacuación temporal de decenas de familias del casco urbano | AB29: No documentado | AC29: Preliminar | AD29: https://www.infobae.com/colombia/2026/10/04/atacan-con-explosivos-y-rafagas-de-fusil-una-estacion-de-policia-en-narino-esto-se-sabe/ | AE29: https://citytv.eltiempo.com/noticias/nacional/ataque-con-drones-y-fusiles-en-narino-obligo-evacuar-decenas-de-familias_95932 | AF29: https://www.lafm.com.co/orden-publico/colombia-narino-el-penol-hostigamiento-armado-drones-explosivos-412937 | AG29: =COUNTIF(AD29:AF29,"?*") | AH29: 2026-10-21
A30: CO-2026-029 | B30: 46312 | C30: Sin dato | D30: Arauca | E30: Arauquita | F30: Sector Puente Quinay | G30: 7.03 | H30: -71.43 | I30: Municipal aproximada | J30: Hostigamiento con explosivos lanzados desde un vehículo en movimiento contra tropas del Batallón de Infantería N.º 59 | K30: Granada / artefacto lanzado | L30: Fuerza Pública | M30: Ataque armado contra Fuerza Pública (clasificación analítica provisional) | N30: Comisión Martha Elena Barón del ELN (atribución preliminar del Ejército) | O30: ELN | P30: B | Q30: 0 | R30: 1 | S30: 0 | T30: 0 | U30: =Q30+R30 | V30: =S30+T30 | W30: Un soldado profesional herido por esquirlas que murió después (balance del Ejército, 21-oct). | X30: El Ejército atribuyó el hecho a esa estructura del ELN, en términos preliminares. | Y30: No informados. | Z30: No cuantificado | AA30: No documentado | AB30: No documentado | AC30: Confirmado | AD30: https://www.semana.com/nacion/articulo/soldado-resulto-herido-en-un-ataque-con-explosivos-atribuido-preliminarmente-al-eln-en-arauca/202645/ | AE30: https://www.eluniversal.com.co/sucesos/2026/10/21/no-resistio-murio-daniel-felipe-pinzon-el-soldado-herido-en-ataque-con-explosivos/ | AF30: https://www.elheraldo.co/colombia/2026/10/18/un-soldado-resulto-herido-en-ataque-del-eln-con-explosivos-en-arauca/ | AG30: =COUNTIF(AD30:AF30,"?*") | AH30: 2026-10-21
A31: CO-2026-030 | B31: 46257 | C31: Sin dato | D31: Chocó | E31: Nóvita | F31: Subregión del San Juan, entre Sipí y Nóvita (lugar exacto no precisado) | G31: 4.95 | H31: -76.64 | I31: Municipal aproximada | J31: Ataque con un artefacto aéreo no tripulado cargado con explosivos improvisados que dejó civiles heridos | K31: Dron con explosivos | L31: Población civil | M31: Incierto – autoría y finalidad no establecidas | N31: No atribuido: la Defensoría describe el contexto de combates entre el Clan del Golfo y el ELN, sin atribuir el ataque | O31: No determinado | P31: E | Q31: 0 | R31: 0 | S31: 3 | T31: 0 | U31: =Q31+R31 | V31: =S31+T31 | W31: Tres civiles heridos (dos hombres y una mujer). | X31: La Defensoría del Pueblo no atribuye el ataque con dron a ningún grupo. | Y31: No informados. | Z31: No cuantificado | AA31: Desplazamiento y confinamiento de unas 405 familias (1.366 personas) en Nóvita y Sipí por combates entre EGC y ELN, según la Defensoría; no atribuible solo a este hecho | AB31: No documentado | AC31: Preliminar | AD31: https://www.defensoria.gov.co/-/enfrentamientos-armados-en-la-subregion-del-san-juan-en-el-departamento-de-choco-generan-desplazamiento-y-confinamiento | AG31: =COUNTIF(AD31:AF31,"?*") | AH31: 2026-10-21
A32: CO-2026-031 | B32: 46308 | C32: 15:20 | D32: Valle del Cauca | E32: Dagua | F32: Corregimiento El Queremal, subestación de Policía | G32: 3.65 | H32: -76.69 | I32: Municipal aproximada | J32: Ataque con dos artefactos explosivos lanzados desde drones contra una subestación de Policía, con civiles heridos | K32: Dron con explosivos | L32: Fuerza Pública | M32: Presunto acto terrorista (clasificación analítica provisional) | N32: No atribuido formalmente: las autoridades señalan a la estructura Jaime Martínez como riesgo en la zona, pero indican que la responsabilidad requiere investigación | O32: No determinado | P32: E | Q32: 0 | R32: 0 | S32: 4 | T32: 0 | U32: =Q32+R32 | V32: =S32+T32 | W32: Cuatro civiles heridos según el primer balance (esquirlas y aturdimiento); el balance podría no ser definitivo. | X32: Las fuentes consultadas no recogen una atribución oficial de este ataque; la mención a disidencias proviene de información de prensa. | Y32: Daños estructurales en la subestación de Policía; el segundo artefacto detonó cerca de un establecimiento comercial. | Z32: No cuantificado | AA32: No documentado | AB32: No documentado | AC32: Preliminar | AD32: https://www.diariodelsur.com.co/noticias/ataque-con-explosivos-en-dagua-deja-cuatro-civiles-heridos | AE32: https://www.semana.com/nacion/articulo/ataque-con-explosivos-aereos-contra-la-policia-en-dagua-enciende-las-alarmas-en-el-valle-del-cauca/202608/ | AG32: =COUNTIF(AD32:AF32,"?*") | AH32: 2026-10-22
A33: CO-2026-032 | B33: 46318 | C33: Madrugada | D33: Casanare | E33: Villanueva | F33: Peaje San Pedro, vía Villanueva–Monterrey | G33: 4.61 | H33: -72.93 | I33: Municipal aproximada | J33: Explosión de un presunto carro bomba en un peaje; según versiones preliminares, dos hombres dejaron un vehículo y huyeron en motocicleta | K33: Vehículo con explosivos | L33: Infraestructura vial | M33: Presunto acto terrorista (clasificación analítica provisional) | N33: No atribuido formalmente: la gobernación ofreció recompensa por los responsables y se investiga | O33: No determinado | P33: E | Q33: 0 | R33: 0 | S33: 5 | T33: 0 | U33: =Q33+R33 | V33: =S33+T33 | W33: Cinco heridos según el último reporte consultado (el primer balance indicaba cuatro). | X33: Las fuentes consultadas no recogen una atribución oficial; las autoridades investigan el hecho. | Y33: Destrucción parcial de la estructura, cabinas y oficinas del peaje; tránsito suspendido. | Z33: No cuantificado | AA33: No documentado | AB33: Cierre temporal de la vía | AC33: Preliminar | AD33: https://www.infobae.com/colombia/2026/10/23/explosion-de-un-presunto-carro-bomba-en-peaje-de-casanare-deja-cuatro-heridos-investigan-atentado/ | AE33: https://www.noticiasrcn.com/colombia/artefacto-explosivo-detono-al-paso-de-patrulla-en-puerto-santander-1074715 | AG33: =COUNTIF(AD33:AF33,"?*") | AH33: 2026-10-24
A34: CO-2026-033 | B34: 46318 | C34: Día | D34: Cauca | E34: Guapi | F34: Sector Bonanza, zona rural | G34: 2.57 | H34: -77.89 | I34: Municipal aproximada | J34: Ataque con artefactos explosivos lanzados desde drones contra unidades de la Armada Nacional que adelantaban operaciones | K34: Dron con explosivos | L34: Fuerza Pública | M34: Presunto acto terrorista (clasificación analítica provisional) | N34: Estructura 30 «Jhonier Toro Arenas», Bloque Occidental «Jacobo Arenas» de las disidencias de las Farc (atribución preliminar de las autoridades) | O34: Disidencias FARC | P34: B | Q34: 0 | R34: 1 | S34: 0 | T34: 4 | U34: =Q34+R34 | V34: =S34+T34 | W34: Un infante de Marina muerto y cuatro uniformados heridos (tres infantes de Marina profesionales y un suboficial), evacuados a Cali. | X34: Según información preliminar de las autoridades, el ataque lo habrían cometido integrantes de esa estructura; es una hipótesis oficial, no una conclusión confirmada. | Y34: Daños en la lancha utilizada por la unidad. | Z34: No cuantificado | AA34: No documentado | AB34: No documentado | AC34: Preliminar | AD34: https://www.elpais.com.co/judicial/un-infante-de-marina-murio-y-cuatro-militares-resultaron-heridos-tras-ataque-con-explosivos-en-zona-rural-de-guapi-2343.html | AE34: https://www.eluniversal.com.co/sucesos/2026/10/24/edwin-andres-vargas-el-infante-de-marina-que-murio-en-ataque-con-dron/ | AG34: =COUNTIF(AD34:AF34,"?*") | AH34: 2026-10-25
A35: CO-2026-034 | B35: 46318 | C35: Madrugada | D35: Norte de Santander | E35: Puerto Santander | F35: Vía urbana, área metropolitana de Cúcuta | G35: 8.36 | H35: -72.41 | I35: Municipal aproximada | J35: Detonación de un artefacto explosivo instalado al paso de una patrulla motorizada de la Policía | K35: Explosivo / IED | L35: Fuerza Pública | M35: Presunto acto terrorista (clasificación analítica provisional) | N35: No atribuido formalmente: las autoridades investigan | O35: No determinado | P35: E | Q35: 0 | R35: 0 | S35: 0 | T35: 0 | U35: =Q35+R35 | V35: =S35+T35 | W35: Uniformados ilesos. | X35: La fuente consultada no recoge una atribución oficial. | Y35: Afectación de la vía (tierra y material vegetal sobre la calzada); sin mayores daños. | Z35: No cuantificado | AA35: No documentado | AB35: No documentado | AC35: Preliminar | AD35: https://www.noticiasrcn.com/colombia/artefacto-explosivo-detono-al-paso-de-patrulla-en-puerto-santander-1074715 | AG35: =COUNTIF(AD35:AF35,"?*") | AH35: 2026-10-24

Sheet Indicadores
A1: Indicadores (todas las cifras se calculan con fórmulas sobre la hoja Incidentes)
A3: Indicador | B3: Valor
A4: Incidentes | B4: =COUNTA(Incidentes!$A$2:$A$35)
A5: Fallecidos | B5: =SUM(Incidentes!$U$2:$U$35)
A6: de ellos, Fuerza Pública | B6: =SUM(Incidentes!$R$2:$R$35)
A7: de ellos, civiles | B7: =SUM(Incidentes!$Q$2:$Q$35)
A8: Heridos | B8: =SUM(Incidentes!$V$2:$V$35)
A9: de ellos, Fuerza Pública | B9: =SUM(Incidentes!$T$2:$T$35)
A10: de ellos, civiles | B10: =SUM(Incidentes!$S$2:$S$35)
A11: Civiles afectados (fallecidos + heridos) | B11: =B7+B10
A12: Departamentos con incidentes | B12: =SUMPRODUCT(1/COUNTIF(Incidentes!$D$2:$D$35,Incidentes!$D$2:$D$35))
A13: Municipios con incidentes | B13: =SUMPRODUCT(1/COUNTIFS(Incidentes!$D$2:$D$35,Incidentes!$D$2:$D$35,Incidentes!$E$2:$E$35,Incidentes!$E$2:$E$35))
A14: Atribuidos al ELN (presunto) | B14: =COUNTIF(Incidentes!$O$2:$O$35,"ELN")
A15: Atribuidos a disidencias de las FARC (presunto) | B15: =COUNTIF(Incidentes!$O$2:$O$35,"Disidencias FARC")
A16: Otros actores | B16: =B4-B14-B15-COUNTIF(Incidentes!$O$2:$O$35,"No determinado")
A17: Autoría desconocida (atribución E) | B17: =COUNTIF(Incidentes!$P$2:$P$35,"E")
A18: % sin autor determinado | B18: =B17/B4
A19: Registros con fuente única | B19: =COUNTIF(Incidentes!$AG$2:$AG$35,1)
A20: % con información incompleta (fuente única, preliminar o en investigación) | B20: =SUMPRODUCT(--(((Incidentes!$AG$2:$AG$35=1)+ISNUMBER(SEARCH("Preliminar",Incidentes!$AC$2:$AC$35))+ISNUMBER(SEARCH("investigación",Incidentes!$AC$2:$AC$35)))>0))/B4
A23: Por grupo | B23: Incidentes | C23: Fallecidos | D23: Heridos
A24: ELN | B24: =COUNTIF(Incidentes!$O$2:$O$35,A24) | C24: =SUMIF(Incidentes!$O$2:$O$35,A24,Incidentes!$U$2:$U$35) | D24: =SUMIF(Incidentes!$O$2:$O$35,A24,Incidentes!$V$2:$V$35)
A25: Disidencias FARC | B25: =COUNTIF(Incidentes!$O$2:$O$35,A25) | C25: =SUMIF(Incidentes!$O$2:$O$35,A25,Incidentes!$U$2:$U$35) | D25: =SUMIF(Incidentes!$O$2:$O$35,A25,Incidentes!$V$2:$V$35)
A26: Clan del Golfo / EGC | B26: =COUNTIF(Incidentes!$O$2:$O$35,A26) | C26: =SUMIF(Incidentes!$O$2:$O$35,A26,Incidentes!$U$2:$U$35) | D26: =SUMIF(Incidentes!$O$2:$O$35,A26,Incidentes!$V$2:$V$35)
A27: ACSN | B27: =COUNTIF(Incidentes!$O$2:$O$35,A27) | C27: =SUMIF(Incidentes!$O$2:$O$35,A27,Incidentes!$U$2:$U$35) | D27: =SUMIF(Incidentes!$O$2:$O$35,A27,Incidentes!$V$2:$V$35)
A28: Autor individual (capturado) | B28: =COUNTIF(Incidentes!$O$2:$O$35,A28) | C28: =SUMIF(Incidentes!$O$2:$O$35,A28,Incidentes!$U$2:$U$35) | D28: =SUMIF(Incidentes!$O$2:$O$35,A28,Incidentes!$V$2:$V$35)
A29: No determinado | B29: =COUNTIF(Incidentes!$O$2:$O$35,A29) | C29: =SUMIF(Incidentes!$O$2:$O$35,A29,Incidentes!$U$2:$U$35) | D29: =SUMIF(Incidentes!$O$2:$O$35,A29,Incidentes!$V$2:$V$35)
A32: Por tipo de atribución | B32: Incidentes
A33: A · Judicial | B33: =COUNTIF(Incidentes!$P$2:$P$35,"A")
A34: B · Oficial | B34: =COUNTIF(Incidentes!$P$2:$P$35,"B")
A35: C · Reivindicada | B35: =COUNTIF(Incidentes!$P$2:$P$35,"C")
A36: D · Hipótesis periodística o de terceros | B36: =COUNTIF(Incidentes!$P$2:$P$35,"D")
A37: E · Desconocida | B37: =COUNTIF(Incidentes!$P$2:$P$35,"E")
A40: Por departamento | B40: Incidentes | C40: Fallecidos | D40: Heridos | E40: Sin autor (E) | F40: % sin autor
A41: Arauca | B41: =COUNTIF(Incidentes!$D$2:$D$35,A41) | C41: =SUMIF(Incidentes!$D$2:$D$35,A41,Incidentes!$U$2:$U$35) | D41: =SUMIF(Incidentes!$D$2:$D$35,A41,Incidentes!$V$2:$V$35) | E41: =COUNTIFS(Incidentes!$D$2:$D$35,A41,Incidentes!$P$2:$P$35,"E") | F41: =E41/B41
A42: Casanare | B42: =COUNTIF(Incidentes!$D$2:$D$35,A42) | C42: =SUMIF(Incidentes!$D$2:$D$35,A42,Incidentes!$U$2:$U$35) | D42: =SUMIF(Incidentes!$D$2:$D$35,A42,Incidentes!$V$2:$V$35) | E42: =COUNTIFS(Incidentes!$D$2:$D$35,A42,Incidentes!$P$2:$P$35,"E") | F42: =E42/B42
A43: Cauca | B43: =COUNTIF(Incidentes!$D$2:$D$35,A43) | C43: =SUMIF(Incidentes!$D$2:$D$35,A43,Incidentes!$U$2:$U$35) | D43: =SUMIF(Incidentes!$D$2:$D$35,A43,Incidentes!$V$2:$V$35) | E43: =COUNTIFS(Incidentes!$D$2:$D$35,A43,Incidentes!$P$2:$P$35,"E") | F43: =E43/B43
A44: Cesar | B44: =COUNTIF(Incidentes!$D$2:$D$35,A44) | C44: =SUMIF(Incidentes!$D$2:$D$35,A44,Incidentes!$U$2:$U$35) | D44: =SUMIF(Incidentes!$D$2:$D$35,A44,Incidentes!$V$2:$V$35) | E44: =COUNTIFS(Incidentes!$D$2:$D$35,A44,Incidentes!$P$2:$P$35,"E") | F44: =E44/B44
A45: Chocó | B45: =COUNTIF(Incidentes!$D$2:$D$35,A45) | C45: =SUMIF(Incidentes!$D$2:$D$35,A45,Incidentes!$U$2:$U$35) | D45: =SUMIF(Incidentes!$D$2:$D$35,A45,Incidentes!$V$2:$V$35) | E45: =COUNTIFS(Incidentes!$D$2:$D$35,A45,Incidentes!$P$2:$P$35,"E") | F45: =E45/B45
A46: Huila | B46: =COUNTIF(Incidentes!$D$2:$D$35,A46) | C46: =SUMIF(Incidentes!$D$2:$D$35,A46,Incidentes!$U$2:$U$35) | D46: =SUMIF(Incidentes!$D$2:$D$35,A46,Incidentes!$V$2:$V$35) | E46: =COUNTIFS(Incidentes!$D$2:$D$35,A46,Incidentes!$P$2:$P$35,"E") | F46: =E46/B46
A47: La Guajira | B47: =COUNTIF(Incidentes!$D$2:$D$35,A47) | C47: =SUMIF(Incidentes!$D$2:$D$35,A47,Incidentes!$U$2:$U$35) | D47: =SUMIF(Incidentes!$D$2:$D$35,A47,Incidentes!$V$2:$V$35) | E47: =COUNTIFS(Incidentes!$D$2:$D$35,A47,Incidentes!$P$2:$P$35,"E") | F47: =E47/B47
...

Sheet Fuentes
A1: Id | B1: URL | C1: Dominio
A2: CO-2026-001 | B2: https://www.bluradio.com/nacion/atacan-con-explosivos-la-alcaldia-de-teruel-huila-hay-un-herido-so35 | C2: bluradio.com
A3: CO-2026-002 | B3: https://www.aljazeera.com/news/2026/8/8/car-bomb-attack-rattles-colombia-after-inauguration-of-hardline-president | C3: aljazeera.com
A4: CO-2026-002 | B4: https://www.teleamazonas.com/actualidad/noticias/internacional/cronologia-violencia-colombia-atentados-seguridad-129149/ | C4: teleamazonas.com
A5: CO-2026-003 | B5: https://www.latribuna.hn/2026/08/08/policia-muere-en-ataque-con-explosivos-lanzados-desde-drones-en-colombia/ | C5: latribuna.hn
A6: CO-2026-003 | B6: https://www.minuto30.com/?p=1715502 | C6: minuto30.com
A7: CO-2026-003 | B7: https://www.teleamazonas.com/actualidad/noticias/internacional/cronologia-violencia-colombia-atentados-seguridad-129149/ | C7: teleamazonas.com
A8: CO-2026-004 | B8: https://www.infobae.com/america/agencias/2026/08/16/al-menos-un-militar-muerto-y-otros-cinco-heridos-en-un-ataque-del-eln-en-el-noreste-de-colombia/ | C8: infobae.com
A9: CO-2026-004 | B9: https://www.teleamazonas.com/actualidad/noticias/internacional/10-hechos-violentos-colombia-atentados-espriella-129149/ | C9: teleamazonas.com
A10: CO-2026-005 | B10: https://www.noticiasrcn.com/colombia/lanzan-granadas-contra-batallon-en-pelaya-cesar-1054870 | C10: noticiasrcn.com
A11: CO-2026-005 | B11: https://lapatilla.com/2026/08/27/al-menos-dos-soldados-fueron-heridos-por-ataque-con-explosivos-en-el-norte-de-colombia/ | C11: lapatilla.com
A12: CO-2026-005 | B12: https://www.teleamazonas.com/actualidad/noticias/internacional/cronologia-violencia-colombia-atentados-seguridad-129149/ | C12: teleamazonas.com
... A71: CO-2026-034 | B71: https://www.noticiasrcn.com/colombia/artefacto-explosivo-detono-al-paso-de-patrulla-en-puerto-santander-1074715 | C71: noticiasrcn.com
A73: Contexto agregado (no se suma a la base)
A74: Fuente | B74: Cifra agregada descrita | C74: URL
A75: Balance de la fuerza pública citado por El Tiempo (vía Teleamazonas) | B75: 292 ataques con drones en 2026 con corte al 15-sep-2026, frente a 277 en todo 2025. Fuente secundaria; no se verificó el balance original. | C75: https://www.teleamazonas.com/actualidad/noticias/internacional/cronologia-violencia-colombia-atentados-seguridad-129149/
A76: El Tiempo, citado por Infobae (2-sep-2026) | B76: Al menos 204 atentados con explosivos en 2026: 174 hasta el 30-jul y al menos 30 en agosto; al menos 75 atribuidos al ELN. | C76: https://www.infobae.com/colombia/2026/09/02/atentados-con-explosivos-en-colombia-llegan-a-204-en-2026-tras-carro-bomba-en-los-patios/
A77: Defensoría del Pueblo, citada por Al Jazeera (18-sep-2026) | B77: Los ataques con drones contra la Fuerza Pública aumentaron 146 % entre enero y mayo de 2026 frente al mismo periodo de 2025. | C77: https://www.aljazeera.com/amp/news/2026/9/18/drone-attacks-by-colombian-armed-groups-more-than-double-in-early-2026

Sheet Excluidos y pendientes
A1: Fecha | B1: Departamento | C1: Municipio | D1: Hecho reportado | E1: Justificación
A2: 2026-08-01 | B2: Norte de Santander | C2: Cúcuta | D2: Carro bomba cerca del comando de Policía (11 heridos) | E2: Fuera del periodo: ocurrió antes del 7-ago-2026.
A3: 2026-08-02 | B3: Huila | C3: Íquira | D3: Ataque con explosivos a una instalación policial (2 policías heridos) | E3: Fuera del periodo; solo se conoce por una mención en otra nota.
A4: 2026-09-21 | B4: Magdalena | C4: Santa Marta (Guachaca) | D4: Operativo de la Fuerza Pública contra las ACSN: siete presuntos integrantes muertos y tres capturados | E4: Operación de la Fuerza Pública (combate); no es acto de violencia contra la población. Se registra solo la reacción posterior (CO-2026-011).
A5: 2026-10-06 | B5: Cauca | C5: Santander de Quilichao | D5: Hallazgo de más de 400 kg de explosivo en un camión de la vía Panamericana | E5: Atentado frustrado sin detonación.
A6: 2026-10-05 | B6: Caquetá | C6: Sin dato | D6: Combate con un soldado muerto y dos capturados | E6: Combate o enfrentamiento; no se documenta ataque contra la población ni acción terrorista.
A7: 2026-10-17 | B7: Norte de Santander | C7: Tibú y Sardinata | D7: Combates entre el ELN y disidencias, desplazamientos y lanzamiento de explosivos desde drones cerca de población | E7: Enfrentamiento entre grupos armados; sin víctimas confirmadas ni autor del lanzamiento determinado en las fuentes.
A8: 2026-10-12 | B8: Cauca | C8: El Bordo (Patía) | D8: Atentado contra un peaje | E8: Fecha y daños no verificados: solo se halló un titular sin detalles.
A9: 2026-10-12 | B9: Cauca | C9: Sin dato | D9: Ataque con dos policías heridos atribuido preliminarmente a la estructura Dagoberto Ramos | E9: Pendiente: solo hay un resumen de segunda mano sin lugar ni cifras verificables.
A10: 2026-10-05 | B10: Cauca | C10: Sin dato | D10: Policía o suboficial muerto en un ataque armado dentro de la semana del 5 al 10 de octubre | E10: Pendiente: fecha, lugar y cargo de la víctima no verificados (la nota original no pudo consultarse).
A11: 2026-10-16 | B11: Huila | C11: Íquira | D11: Hostigamiento en el casco urbano (noche del viernes 16-oct) | E11: Pendiente: la Defensoría lo menciona sin cifras ni modalidad.
A12: 2026-10-17 | B12: Nariño | C12: Linares y Los Andes | D12: Enfrentamientos armados entre el EMC (Mordisco) y las Autodefensas Unidas de Nariño con riesgo para comunidades | E12: Enfrentamiento entre grupos armados; la Defensoría no reporta ataque contra población o Fuerza Pública.
... A23: 2026-09-01 | B23: Cauca | C23: Sin dato | D23: Ataque con drones que dejó siete civiles heridos (El Tiempo) | E23: Fecha no verificable en la nota consultada; podría corresponder a hechos de junio en Suárez.

Sheet Metodología
A1: Tema | B1: Criterio
A2: 1. Alcance temporal y territorial | B2: Hechos ocurridos en Colombia desde el 7 de agosto de 2026 (00:00, UTC−5) hasta la fecha de corte.
A3: 2. Alcance temático | B3: Presuntos actos terroristas, atentados, ataques armados y otras acciones violentas relevantes. No se equipara el terrorismo con cualquier violencia.
A4: 3. Fuentes | B4: Fuentes abiertas: entidades oficiales, agencias y medios nacionales y regionales. Se leyó cada nota citada; las fuentes que no pudieron consultarse no se citan como leídas.
A5: 4. Inclusión | B5: Un registro por evento verificable con fecha, lugar y modalidad. Los registros con fuente única o estado preliminar se marcan como información incompleta.
A6: 5. Clasificación | B6: La clase analítica es provisional y no es calificación jurídica ni denominación oficial. Se distingue entre calificación jurídica, denominación oficial y clasificación analítica.
A7: 6. Atribución A–E | B7: A judicial · B oficial · C reivindicada · D hipótesis periodística o de terceros · E desconocida. No se infiere autoría por presencia territorial, modalidad, antecedentes o coincidencia geográfica.
A8: 7. Víctimas | B8: Cifra oficial más reciente; No se publican nombres de víctimas.
A9: 8. Coordenadas | B9: Centroide municipal aproximado (WGS84), nunca una ubicación exacta.
A10: 9. Daño económico | B10: No se asignan valores económicos sin fuente con metodología. Una recompensa no es un daño.
A11: 10. Deduplicación | B11: Un registro por evento; varios medios sobre el mismo hecho se consolidan en un solo id. Se excluyen combates, atentados frustrados, hechos fuera del periodo o del territorio y fechas no verificables.
A12: 11. Vacíos y privacidad | B12: La base es una muestra, no el universo. Las cifras agregadas oficiales van aparte y no se suman. No se publica información táctica que facilite ataques.

Sheet Diccionario
A1: Campo | B1: Tipo | C1: Descripción | D1: Valores o regla
A2: id | B2: texto | C2: Identificador consecutivo, nunca se reutiliza | D2: CO-2026-NNN
A3: fecha | B3: fecha | C3: Fecha de ocurrencia (no de publicación) | D3: AAAA-MM-DD, desde 2026-08-07 hasta el corte
A4: hora | B4: texto | C4: Hora o franja | D4: HH:MM, franja o 'Sin dato'
A5: depto, mpio, lugar | B5: texto | C5: Ubicación; lugar es vereda, barrio o sector si está documentado
A6: lat, lon | B6: número | C6: Centroide municipal aproximado (WGS84) | D6: Lat −4,3 a 13,5; lon −79,1 a −66,8
A7: prec_coord | B7: texto | C7: Precisión de la coordenada | D7: Municipal aproximada · Departamental aproximada
A8: tipo | B8: texto | C8: Modalidad descrita por las fuentes
A9: mod | B9: texto | C9: Categoría controlada | D9: Dron con explosivos · Vehículo con explosivos · Explosivo / IED · Granada / artefacto lanzado · Paro armado · Homicidio selectivo · Ataque armado
A10: objetivo | B10: texto | C10: Población, Fuerza Pública, infraestructura u otro
A11: clase | B11: texto | C11: Clasificación analítica provisional
A12: autor | B12: texto | C12: Actor mencionado por las fuentes
A13: grupo | B13: texto | C13: Agregado para los indicadores | D13: ELN · Disidencias FARC · Clan del Golfo / EGC · ACSN · Autor individual (capturado) · No determinado
A14: atrib | B14: texto | C14: Tipo de atribución | D14: A judicial · B oficial · C reivindicada · D hipótesis · E desconocida
A15: evidencia | B15: texto | C15: Fundamento público de la atribución
A16: m_civ, m_fp, h_civ, h_fp | B16: entero | C16: Muertos y heridos, civiles y Fuerza Pública; cifra oficial más reciente | D16: ≥ 0
A17: h_nota | B17: texto | C17: Precisiones sobre las víctimas
A18: danos, eco, desplaz, servicios | B18: texto | C18: Daños verificables; eco = 'No cuantificado' si no hay fuente
A19: estado | B19: texto | C19: Estado del registro | D19: Confirmado · Preliminar · En investigación
A20: fuentes | B20: lista | C20: 1 a 3 URL verificables | D20: https://
A21: actualizacion | B21: fecha | C21: Fecha de la última verificación
A22: Total muertos / heridos / N.º fuentes | B22: fórmula | C22: Calculados en la hoja Incidentes | D22: Fórmulas: Q+R · S+T · COUNTIF(AD:AF,"?*")
